<?xml version="1.0"?>
<robot xmlns:xacro="http://ros.org/wiki/xacro">
  <xacro:include filename="$(find abb_resources)/urdf/common_materials.xacro"/>

  <xacro:macro name="abb_irb120" params="prefix">
    <!-- link list -->
    <link name="${prefix}base_link">
      <inertial>
        <mass value="6.215"/>
        <origin xyz="-0.04204 8.01E-05 0.07964" rpy="0 0 0"/>
        <inertia ixx="0.0247272" ixy="-8.0784E-05" ixz="0.00130902" iyy="0.0491285" iyz="-8.0419E-06" izz="0.0472376"/>
      </inertial>
      <visual>
        <origin xyz="0 0 0" rpy="0 0 0"/>
        <geometry>
          <mesh filename="package://abb_irb120_support/meshes/irb120/visual/base_link.stl"/>
        </geometry>
        <xacro:material_abb_orange />
      </visual>
      <collision>
        <origin xyz="0 0 0" rpy="0 0 0"/>
        <geometry>
          <mesh filename="package://abb_irb120_support/meshes/irb120/collision/base_link.stl"/>
        </geometry>
        <xacro:material_abb_yellow />
      </collision>
    </link>
    <link name="${prefix}link_1">
      <inertial>
        <mass value="3.067" />
        <origin xyz="9.77E-05 -0.00012 0.23841" rpy="0 0 0"/>
        <inertia ixx="0.0142175" ixy="-1.28579E-05" ixz="-2.31364E-05" iyy="0.0144041" iyz="1.93404E-05" izz="0.0104533"/>
      </inertial>
      <visual>
        <origin xyz="0 0 0" rpy="0 0 0"/>
        <geometry>
          <mesh filename="package://abb_irb120_support/meshes/irb120/visual/link_1.stl"/>
        </geometry>
        <xacro:material_abb_orange />
      </visual>
      <collision>
        <origin xyz="0 0 0" rpy="0 0 0"/>
        <geometry>
          <mesh filename="package://abb_irb120_support/meshes/irb120/collision/link_1.stl"/>
        </geometry>
        <xacro:material_abb_yellow />
      </collision>
    </link>
    <link name="${prefix}link_2">
      <inertial>
        <mass value="3.909"/>
        <origin xyz="0.00078 -0.00212 0.10124" rpy="0 0 0"/>
        <inertia ixx="0.0603111" ixy="9.83431E-06" ixz="5.72407E-05" iyy="0.041569" iyz="-0.00050497" izz="0.0259548"/>
      </inertial>
      <visual>
        <origin xyz="0 0 0" rpy="0 0 0"/>
        <geometry>
          <mesh filename="package://abb_irb120_support/meshes/irb120/visual/link_2.stl"/>
        </geometry>
        <xacro:material_abb_orange />
      </visual>
      <collision>
        <origin xyz="0 0 0" rpy="0 0 0"/>
        <geometry>
          <mesh filename="package://abb_irb120_support/meshes/irb120/collision/link_2.stl"/>
        </geometry>
        <xacro:material_abb_yellow />
      </collision>
    </link>
    <link name="${prefix}link_3">
      <inertial>
        <mass value="2.944"/>
        <origin xyz="0.02281 0.00106 0.05791" rpy="0 0 0"/>
        <inertia ixx="0.00835606" ixy="-8.01545E-05" ixz="0.00142884" iyy="0.016713" iyz="-0.000182227" izz="0.0126984"/>
      </inertial>
      <visual>
        <origin xyz="0 0 0" rpy="0 0 0"/>
        <geometry>
          <mesh filename="package://abb_irb120_support/meshes/irb120/visual/link_3.stl"/>
        </geometry>
        <xacro:material_abb_orange />
      </visual>
      <collision>
        <origin xyz="0 0 0" rpy="0 0 0"/>
        <geometry>
          <mesh filename="package://abb_irb120_support/meshes/irb120/collision/link_3.stl"/>
        </geometry>
        <xacro:material_abb_yellow />
      </collision>
    </link>
    <link name="${prefix}link_4">
      <inertial>
        <mass value="1.328"/>
        <origin xyz="0.2247 0.00015 0.00041" rpy="0 0 0"/>
        <inertia ixx="0.00284661" ixy="-2.12765E-05" ixz="-1.6435E-05" iyy="0.00401346" iyz="1.31336E-05" izz="0.0052535"/>
      </inertial>
      <visual>
        <origin xyz="0 0 0" rpy="0 0 0"/>
        <geometry>
          <mesh filename="package://abb_irb120_support/meshes/irb120/visual/link_4.stl"/>
        </geometry>
        <xacro:material_abb_orange />
      </visual>
      <collision>
        <origin xyz="0 0 0" rpy="0 0 0"/>
        <geometry>
          <mesh filename="package://abb_irb120_support/meshes/irb120/collision/link_4.stl"/>
        </geometry>
        <xacro:material_abb_yellow />
      </collision>
    </link>
    <link name="${prefix}link_5">
      <inertial>
        <mass value="0.546"/>
        <origin xyz="-0.00109 3.68E-05 6.22E-05" rpy="0 0 0"/>
        <inertia ixx="0.000404891" ixy="1.61943E-06" ixz="8.46805E-07" iyy="0.000892825" iyz="-1.51792E-08" izz="0.000815468"/>
      </inertial>
      <visual>
        <origin xyz="0 0 0" rpy="0 0 0"/>
        <geometry>
          <mesh filename="package://abb_irb120_support/meshes/irb120/visual/link_5.stl"/>
        </geometry>
        <xacro:material_abb_orange />
      </visual>
      <collision>
        <origin xyz="0 0 0" rpy="0 0 0"/>
        <geometry>
          <mesh filename="package://abb_irb120_support/meshes/irb120/collision/link_5.stl"/>
        </geometry>
        <xacro:material_abb_yellow />
      </collision>
    </link>
    <link name="${prefix}link_6">
      <inertial>
        <mass value="0.137"/>
        <origin xyz="-0.00706 -0.00017 -1.32E-06" rpy="0 0 0"/>
        <inertia ixx="0.001" ixy="0" ixz="0" iyy="0.001" iyz="0" izz="0.001"/>
      </inertial>
      <visual>
        <origin xyz="0 0 0" rpy="0 0 0"/>
        <geometry>
          <mesh filename="package://abb_irb120_support/meshes/irb120/visual/link_6.stl"/>
        </geometry>
        <xacro:material_abb_black />
      </visual>
      <collision>
        <origin xyz="0 0 0" rpy="0 0 0"/>
        <geometry>
          <mesh filename="package://abb_irb120_support/meshes/irb120/collision/link_6.stl"/>
        </geometry>
        <xacro:material_abb_yellow />
      </collision>
    </link>
  <link name="${prefix}tool0">
    <origin rpy="0 0 0" xyz="0 0 0"/>
    <visual>
      <origin rpy="0 0 0" xyz="-0.062 0 0"/>
      <geometry>
        <box size="0.125 0.005 0.005"/>
      </geometry>
        <material name="orange"/>
    </visual>
    <collision>
      <origin rpy="0 0 0" xyz="-0.062 0 0"/>
      <geometry>
        <box size="0.125 0.005 0.005"/>
      </geometry>
      </collision>
  </link>    
<!--link name="${prefix}left_gripper_link">
        <visual>
            <geometry>
                <box size="0.03 0.015 0.015" />
            </geometry>        
        <material name="orange"/>
        </visual>        
    </link>
<link name="${prefix}right_gripper_link">
        <visual>
            <geometry>
                <box size="0.03 0.015 0.015" />
            </geometry>      
        <material name="orange">
        <color rgba="0.1882353 0.1960784 0.2039216 1"/>
      </material>
        </visual>        
    </link-->
    <!-- end of link list -->

    <!-- joint list -->
    <joint name="${prefix}joint_1" type="revolute">
      <origin rpy="0 0 0" xyz="0 0 0"/>
      <parent link="${prefix}base_link"/>
      <child link="${prefix}link_1"/>
      <limit effort="0" lower="-2.87979" upper="2.87979" velocity="4.36332"/>
      <axis xyz="0 0 1"/>
      <dynamics damping="0.0" friction="0.0"/>
    </joint>
    <joint name="${prefix}joint_2" type="revolute">
      <origin rpy="0 0 0" xyz="0 0 0.29"/>
      <parent link="${prefix}link_1"/>
      <child link="${prefix}link_2"/>
      <limit effort="0" lower="-1.91986" upper="1.91986" velocity="4.36332"/>
      <axis xyz="0 1 0"/>
      <dynamics damping="0.0" friction="0.0"/>
    </joint>
    <joint name="${prefix}joint_3" type="revolute">
      <origin rpy="0 0 0" xyz="0 0 0.27"/>
      <parent link="${prefix}link_2"/>
      <child link="${prefix}link_3"/>
      <limit effort="0" lower="-1.91986" upper="1.22173" velocity="4.36332"/>
      <axis xyz="0 1 0"/>
      <dynamics damping="0.0" friction="0.0"/>
    </joint>
    <joint name="${prefix}joint_4" type="revolute">
      <origin rpy="0 0 0" xyz="0 0 0.07"/>
      <parent link="${prefix}link_3"/>
      <child link="${prefix}link_4"/>
      <limit effort="0" lower="-2.79253" upper="2.79253" velocity="5.58505"/>
      <axis xyz="1 0 0"/>
      <dynamics damping="0.0" friction="0.0"/>
    </joint>
    <joint name="${prefix}joint_5" type="revolute">
      <origin rpy="0 0 0" xyz="0.302 0 0"/>
      <parent link="${prefix}link_4"/>
      <child link="${prefix}link_5"/>
      <limit effort="0" lower="-2.094395" upper="2.094395" velocity="5.58505"/>
      <axis xyz="0 1 0"/>
      <dynamics damping="0.0" friction="0.0"/>
    </joint>
    <joint name="${prefix}joint_6" type="revolute">
      <origin rpy="0 0 0" xyz="0.072 0 0"/>
      <parent link="${prefix}link_5"/>
      <child link="${prefix}link_6"/>
      <limit effort="0" lower="0" upper="6.98132" velocity="7.33038"/>
      <axis xyz="1 0 0"/>
      <dynamics damping="0.0" friction="0.0"/>
    </joint>
    <joint name="${prefix}joint6-tool0" type="fixed">
      <parent link="${prefix}link_6"/>
      <child link="${prefix}tool0"/>
    <origin rpy="0 0 0" xyz="0.125 0 0"/>
    </joint>
  <!--joint name="${prefix}left_gripper_joint" type="prismatic">
    <parent link="${prefix}tool0"/>
    <child link="${prefix}left_gripper_link"/>
    <axis xyz="0 1 0"/>
    <limit lower="-0.02" upper="-0.01" effort="0" velocity="1" />   
    <origin rpy="0 0 0" xyz="0.0505 0 0"/>
  </joint>
  <joint name="${prefix}right_gripper_joint" type="prismatic">
    <parent link="${prefix}tool0"/>
    <child link="${prefix}right_gripper_link"/>
    <axis xyz="0 1 0"/>
    <limit lower="-0.02" upper="-0.01" effort="0" velocity="1" />   
    <origin rpy="0 0 0" xyz="0.0505 0 0"/>
    <mimic joint="${prefix}left_gripper_joint" multiplier="-1" />
  </joint-->
    <!-- end of joint list -->

    <!-- ROS base_link to ABB World Coordinates transform -->
    <link name="${prefix}base" />
    <joint name="${prefix}base_link-base" type="fixed">
      <origin xyz="0 0 0" rpy="0 0 0"/>
      <parent link="${prefix}base_link"/>
      <child link="${prefix}base"/>
    </joint>


      <!-- Boundaries -->    
    <joint name="boundary_floor" type="fixed">
        <origin xyz="0 0 -0.001" rpy="3.14159265359 -1.57079632679 0"/>
      <parent link="base" />
      <child link="floor_link" />
    </joint>
    <joint name="boundary_wall_front" type="fixed">
        <origin xyz="0.5 0 0.536" rpy="-3.14159265359 1.57079632679 0"/>
      <parent link="floor_link" />
      <child link="wall_front_link" />
    </joint>
    <joint name="boundary_wall_back" type="fixed">
        <origin xyz="0.5 0 -0.536" rpy="-3.14159265359 1.57079632679 0"/>
      <parent link="floor_link" />
      <child link="wall_back_link" />
    </joint>
    <joint name="boundary_wall_left" type="fixed">
        <origin xyz="0.5 -0.536 0" rpy=" 1.57079632679 0 1.57079632679"/>
      <parent link="floor_link" />
      <child link="wall_left_link" />
    </joint>
    <joint name="boundary_wall_right" type="fixed">
        <origin xyz="0.5 0.536 0" rpy=" 1.57079632679 0 1.57079632679"/>
      <parent link="floor_link" />
      <child link="wall_right_link" />
    </joint>    

    <link name="floor_link">      
      <inertial>
        <mass value="0.01" />
        <origin xyz="0 0 0" />
        <inertia ixx="0.001"  ixy="0.0"  ixz="0.0"
                 iyy="0.001"  iyz="0.0"
                 izz="0.001" />
      </inertial>
      <visual>
        <geometry>
	  <box size="0.00001 1.07 1.07"/>
        </geometry>
	<material name="walls">
          <color rgba="0 1.0 1.0 0.1"/>
        </material>
      </visual>
      <collision>
        <geometry>
	  <box size="0.00001 1.07 1.07"/>
        </geometry>
      </collision>
    </link>

    <link name="wall_front_link">      
      <inertial>
        <mass value="0.01" />
        <origin xyz="0 0 0" />
        <inertia ixx="0.001"  ixy="0.0"  ixz="0.0"
                 iyy="0.001"  iyz="0.0"
                 izz="0.001" />
      </inertial>
      <visual>
        <geometry>
	  <box size="0.00001 1.07 1.0"/>
        </geometry>
	<material name="walls">
        </material>
      </visual>
      <collision>
        <geometry>
	  <box size="0.00001 1.07 1.0"/>
        </geometry>
      </collision>
    </link>

    <link name="wall_back_link">      
      <inertial>
        <mass value="0.01" />
        <origin xyz="0 0 0" />
        <inertia ixx="0.001"  ixy="0.0"  ixz="0.0"
                 iyy="0.001"  iyz="0.0"
                 izz="0.001" />
      </inertial>
      <visual>
        <geometry>
	  <box size="0.00001 1.07 1.0"/>
        </geometry>
	<material name="walls">
        </material>
      </visual>
      <collision>
        <geometry>
	  <box size="0.00001 1.07 1.0"/>
        </geometry>
      </collision>
    </link>

    <link name="wall_left_link">      
      <inertial>
        <mass value="0.01" />
        <origin xyz="0 0 0" />
        <inertia ixx="0.001"  ixy="0.0"  ixz="0.0"
                 iyy="0.001"  iyz="0.0"
                 izz="0.001" />
      </inertial>
      <visual>
        <geometry>
	  <box size="0.00001 1.07 1.0"/>
        </geometry>
	<material name="walls">
        </material>
      </visual>
      <collision>
        <geometry>
	  <box size="0.00001 1.07 1.0"/>
        </geometry>
      </collision>
    </link>

    <link name="wall_right_link">      
      <inertial>
        <mass value="0.01" />
        <origin xyz="0 0 0" />
        <inertia ixx="0.001"  ixy="0.0"  ixz="0.0"
                 iyy="0.001"  iyz="0.0"
                 izz="0.001" />
      </inertial>
      <visual>
        <geometry>
	  <box size="0.00001 1.07 1.0"/>
        </geometry>
	<material name="walls">
        </material>
      </visual>
      <collision>
        <geometry>
	  <box size="0.00001 1.07 1.0"/>
        </geometry>
      </collision>
    </link>


    <!-- Camera -->    
    <joint name="camera_joint" type="fixed">
        <origin xyz="0.51 0.32 0.524" rpy="3.14159265359 1.95476832679 0"/>
      <parent link="base" />
      <child link="camera_link"/>
    </joint>

    <link name="camera_link">
      <inertial>
        <mass value="0.01" />
        <origin xyz="0.000 0.000 0.000" />
        <inertia ixx="0.001"  ixy="0.0"  ixz="0.0"
                 iyy="0.001"  iyz="0.0"
                 izz="0.001" />
      </inertial>
      <visual>
        <origin xyz="0.1 0 0" rpy="-3.14159265359 -1.95476832679 0" />
        <geometry>         
	  <box size="0.067 0.08 0.07"/>
        </geometry>
	<material name="walls"/>
      </visual>
      <collision>
        <origin xyz="0.1 0 0" rpy="-3.14159265359 -1.95476832679 0" />
        <geometry>	         
	  <box size="0.067 0.08 0.07"/>
	</geometry>
      </collision>
    </link>
     <joint name="camera_view_joint" type="fixed">
        <origin xyz="0.0700 0.1130 0" rpy="0 0 0"/>
      <parent link="base_link" />
      <child link="camera_view_link"/>
    </joint>
    <link name="camera_view_link"/>
     <!--joint name="camera_view_joint" type="fixed">
        <origin xyz="0.654 0.200 0.221" rpy="0 1.187 -3.142"/>
      <parent link="camera_link" />
      <child link="camera_view_link"/>
    </joint>
    <link name="camera_view_link"/-->

  </xacro:macro>
</robot>
